{
 "cells": [
  {
   "cell_type": "code",
   "execution_count": 3,
   "metadata": {},
   "outputs": [],
   "source": [
    "import pandas as pd\n",
    "import numpy as np\n",
    "import openpyxl"
   ]
  },
  {
   "cell_type": "code",
   "execution_count": 4,
   "metadata": {},
   "outputs": [],
   "source": [
    "df_hh = pd.read_excel('homicidios.xlsx', sheet_name='HECHOS')\n",
    "df_hv = pd.read_excel('homicidios.xlsx', sheet_name='VICTIMAS')\n",
    "df_lh = pd.read_excel('lesiones.xlsx', sheet_name='HECHOS')\n",
    "df_lv = pd.read_excel('lesiones.xlsx', sheet_name='VICTIMAS')"
   ]
  },
  {
   "cell_type": "code",
   "execution_count": 8,
   "metadata": {},
   "outputs": [],
   "source": [
    "df_hh.to_csv('hh.csv', encoding='utf8', index=False, quotechar='\"')\n",
    "df_hv.to_csv('hv.csv', encoding='utf8', index=False, quotechar='\"')\n",
    "df_lh.to_csv('lh.csv', encoding='utf8', index=False, quotechar='\"')\n",
    "df_lv.to_csv('lv.csv', encoding='utf8', index=False, quotechar='\"')\n"
   ]
  },
  {
   "cell_type": "markdown",
   "metadata": {},
   "source": [
    "Me tira un error al querer actualizar el repo:\n",
    "\n",
    "PS C:\\Users\\Martin\\Desktop\\Mis Proyectos\\Siniestros_Viales> git push origin master\n",
    "To https://github.com/jmartindiaz/Siniestros_Viales.git\n",
    " ! [rejected]        master -> master (fetch first)\n",
    "error: failed to push some refs to 'https://github.com/jmartindiaz/Siniestros_Viales.git'\n",
    "hint: Updates were rejected because the remote contains work that you do\n",
    "hint: not have locally. This is usually caused by another repository pushing\n",
    "hint: to the same ref. You may want to first integrate the remote changes\n",
    "hint: (e.g., 'git pull ...') before pushing again.\n",
    "hint: See the 'Note about fast-forwards' in 'git push --help' "
   ]
  },
  {
   "cell_type": "markdown",
   "metadata": {},
   "source": [
    "RESUELTO: tuve que fusionar los repositorios remoto y local con 'git pull origin master' (que es lo mismo que hacer primer 'git fetch' y luego git 'merge'). Ahí me salió que habia un conflicto con el README que ya pude solucionar. El repositorio quedó OK."
   ]
  }
 ],
 "metadata": {
  "kernelspec": {
   "display_name": "siniestros_viales-env",
   "language": "python",
   "name": "python3"
  },
  "language_info": {
   "codemirror_mode": {
    "name": "ipython",
    "version": 3
   },
   "file_extension": ".py",
   "mimetype": "text/x-python",
   "name": "python",
   "nbconvert_exporter": "python",
   "pygments_lexer": "ipython3",
   "version": "3.11.1"
  }
 },
 "nbformat": 4,
 "nbformat_minor": 2
}
